Workbook

Sheet README
A1: Adya RAI | Pricing Model 2.0
A2: RAI is the Revenue AI: one agent that runs the whole go-to-market motion. This workbook prices it three ways at once, subscription, usage credits and integrations, so a startup can start cheaply and an enterprise still pays for the scale it uses. Every blue number is an input you can edit. Black numbers are formulas.
B4: The three meters | C4: RAI is priced on three dials, exactly as the product works. Subscription sets the tier and what it includes. Credits meter the work RAI actually does, every email, message, call, lead, signal, asset and report. Integrations cover the thirty-plus tools RAI plugs into and the channel infrastructure (mailboxes, LinkedIn accounts, WhatsApp and voice numbers) that carries the work.
B5: The five-layer stack | C5: Under the hood every RAI deal is built from five layers: (1) a Platform subscription by tier, (2) Seats, kept cheap because RAI is capacity you configure not headcount you recruit, (3) RAI Credits for usage, (4) Integrations and channel infrastructure, and (5) Onboarding and services. A service-level dial (self-serve, assisted, fully-managed) and a commitment discount sit on top.
B6: Why it scales both ways | C6: A solo founder can start free or at $99 and run one channel. An agency or a VC firm running GTM across many portfolio brands scales through brand workspaces, credits and channels into six or seven figures without changing the model. The account grows on the same dials.
B8: Tab | C8: What it holds
B9: Pricing | C9: List pricing for the five tiers: Free, Startup, Growth, Scale, Enterprise. Global ($) and India (₹), with what each tier includes on all three meters.
B10: Segments | C10: Who each tier is for (the locked RAI ICP and buyer personas), what they pay today for the tool stack, and willingness to pay. This justifies the numbers.
B11: Benchmark | C11: How RAI pricing compares to HubSpot, Salesforce Agentforce, Clari, 11x, Artisan, AiSDR, Apollo and Clay. Sourced and dated. Includes the cost of the stack RAI replaces.
B12: Credits | C12: What one RAI Credit is and how each action, email, LinkedIn, WhatsApp, voice, lead, signal, content, research, BI, draws it down. The elastic usage meter.
B13: Integrations | C13: The thirty-plus integration catalogue and the channel-infrastructure units (mailboxes, LinkedIn accounts, WhatsApp, voice, brand workspaces), plus the pass-through policy for third-party data, messaging and ad spend.
B14: Accelerators | C14: The single source of truth for every live rate and assumption QuoteBuilder uses: per-unit rates, deployment, service level, commitment discount, FX.
B15: Services | C15: The one-time-plus-recurring rate card for onboarding, brand-voice training, infrastructure setup, custom integrations and workflows, CRM/BI migration, voice-agent build, white-label, and the self-improving copy model.
B16: QuoteBuilder | C16: A live calculator. Pick a tier, service level, deployment, commitment, then set seats, credits, channels, integrations and services. Returns one-time cost, annual recurring, and Year-1 total. Prefilled with a worked agency example.
B18: Colour legend
B19: Blue text | C19: An input. Change it and the model updates.
B20: Black text | C20: A formula. Do not overwrite; it derives from inputs.
B21: Green text | C21: A link that pulls a number from another tab.
B22: Yellow fill | C22: A key assumption or a cell you should set for your deal.
B24: Note | C24: All numbers are starting hypotheses anchored to competitor pricing and to the real Affinity deal. Calibrate against pilot data before quoting. Large accounts are partner-led per the locked ICP. Economics shown elsewhere are directional (public info plus stated assumptions), not guaranteed customer outcomes.

Sheet Pricing
A1: RAI Pricing | five tiers, three meters
A2: Global list price in USD and the India rupee equivalent for self-serve tiers. Enterprise is partner-led and quoted in USD. Inclusions show what each tier gives you before usage and add-ons.
B4: Tier | C4: Monthly $ | D4: India ₹/mo | E4: Op seats | F4: Rep seats | G4: Credits/mo | H4: Integ. slots | I4: Mailboxes | J4: LinkedIn | K4: Workspaces | L4: For whom / what is on
B5: Free | C5: 0 | D5: =IF(C5=0,0,C5*Accelerators!C5*Accelerators!C6) -> 0 | E5: 1 | F5: 0 | G5: 500 | H5: 1 | I5: 0 | J5: 0 | K5: 1 | L5: Solo founder kicking the tires. One channel (email or LinkedIn), bring-your-own mailbox and LLM key, community support. The wedge.
B6: Startup | C6: 99 | D6: =IF(C6=0,0,C6*Accelerators!C5*Accelerators!C6) -> 4276.8 | E6: 1 | F6: 0 | G6: 3,000 | H6: 5 | I6: 3 | J6: 0 | K6: 1 | L6: Unfunded or solo founder who needs pipeline. Email + LinkedIn, self-serve, three mailboxes included.
B7: Growth | C7: 499 | D7: =IF(C7=0,0,C7*Accelerators!C5*Accelerators!C6) -> 21556.8 | E7: 2 | F7: 5 | G7: 15,000 | H7: 10 | I7: 10 | J7: 2 | K7: 1 | L7: SMB or a small GTM team. Adds WhatsApp, standard CRM and calendar integrations, assisted onboarding, rep visibility.
B8: Scale | C8: 1999 | D8: =IF(C8=0,0,C8*Accelerators!C5*Accelerators!C6) -> 86356.8 | E8: 5 | F8: 25 | G8: 60,000 | H8: 20 | I8: 25 | J8: 6 | K8: 3 | L8: Mid-market, agency or VC portfolio. All channels incl. voice and ads, SSO and audit, up to three brand workspaces, managed-service option.
B9: Enterprise | C9: from 8,500 | D9: quoted USD | E9: 15 | F9: 100 | G9: 400,000 | H9: Unlimited | I9: 100 | J9: 20 | K9: 10 | L9: Partner-led. Agency / VC portfolio / 200-rep visibility. Full AGP governance, white-glove managed, SLA. Builds to $250k-$1M+ on workspaces and volume.
B11: Annual & multi-year | C11: Annual is 15% off, 2-year 22%, 3-year 28% (see Accelerators). Credits, seats, channels and integrations beyond the inclusions are priced on the Accelerators rate card and metered in QuoteBuilder.
B13: Machine-readable inclusions (numbers QuoteBuilder reads; edit here, display table above is cosmetic)
B14: Tier | C14: Base $/mo | D14: Op incl | E14: Rep incl | F14: Credits incl | G14: Integ incl | H14: Mbx incl | I14: LinkedIn incl | J14: Workspace incl
B15: Free | C15: 0 | D15: 1 | E15: 0 | F15: 500 | G15: 1 | H15: 0 | I15: 0 | J15: 1
B16: Startup | C16: 99 | D16: 1 | E16: 0 | F16: 3000 | G16: 5 | H16: 3 | I16: 0 | J16: 1
B17: Growth | C17: 499 | D17: 2 | E17: 5 | F17: 15000 | G17: 10 | H17: 10 | I17: 2 | J17: 1
B18: Scale | C18: 1999 | D18: 5 | E18: 25 | F18: 60000 | G18: 20 | H18: 25 | I18: 6 | J18: 3
B19: Enterprise | C19: 8500 | D19: 15 | E19: 100 | F19: 400000 | G19: 1000000 | H19: 100 | I19: 20 | J19: 10
B21: Note | C21: Enterprise integration allowance is set to a very large number to represent 'unlimited', so QuoteBuilder never charges integration overage on Enterprise. Enterprise base is a floor; edit the base cell for a quoted deal.

Sheet Segments
A1: RAI Segments | who each tier is for and why the price holds
A2: The locked RAI ICP mapped to tiers, what they pay today for the stack RAI replaces, and the willingness-to-pay logic. India first, US second. Large accounts are partner-led.
B4: Tier | C4: Who (ICP + buyer persona) | D4: Pays today for the stack | E4: Willingness to pay / logic
B5: Free / Startup | C5: Solo and unfunded founders; independent operators; tiny startups that cannot hire a salesperson. User and decision maker are the same person. | D5: A patchwork of free trials and one cheap sequencer ($30-60/mo), plus their own time as the orchestrator. | E5: Near-zero friction to enter. The job is to get them running and to prove pipeline, not to make margin. Convert to Growth once volume and value show.
B6: Growth | C6: SMBs and small GTM teams; funded early startups that must scale outbound fast; solopreneurs and marketing agencies starting out. | D6: Apollo or similar ($49-79/seat) + a sequencer + a data tool + content tools, roughly $500-1,500/mo in tools plus a part-time SDR. | E6: $499/mo undercuts a single AI-SDR seat (AiSDR $250-900, Artisan $600) while doing far more than outbound. Priced to be an obvious yes for a team of two to ten.
B7: Scale | C7: Mid-market with an existing sales team that lacks rep-performance visibility (even ~200 reps); agencies running GTM for several clients; VC firms running GTM across a few portfolio brands. | D7: A real stack: Apollo + Clay + Outreach/Salesloft + HubSpot + an AI SDR + content + BI, $4,000-8,000/mo in tools, plus SDR headcount and a RevOps orchestrator. | E7: $1,999/mo base lands most Scale accounts at $30k-80k/yr once channels, credits and workspaces are added, well under the replaced stack, and it removes the headcount and the human glue.
B8: Enterprise | C8: Larger agencies and VC portfolios (many brands), and 200-rep orgs wanting visibility plus execution. Partner-led because Adya has no direct enterprise sales muscle. | D8: $50k-360k/yr on Clari-class RevOps + 11x-class AI SDRs + a full martech stack + the RevOps team. | E8: From ~$102k/yr floor, building to $250k-$1M+ through brand workspaces, credit pools and managed service. Still cheaper than the sum of the tools it replaces, and it is one brain, not a stack that leaks.
B10: Anti-target | C10: Pure D2C/B2C companies whose only RAI use would be ads (RAI is not strong at ads yet). Large accounts are never direct: partner-led only, because the constraint is Adya's sales capacity, not product fit.

Sheet Benchmark
A1: RAI Benchmark | what the market charges, and for how much of the job
A2: Accessed 21 Sep 2026. Every competitor does a slice of what RAI does. The last two rows show the cost of the stack RAI replaces and where RAI sits. Figures are list or widely-reported; sources in the last column.
B4: Competitor | C4: Pricing model | D4: Typical cost | E4: Covers (of RAI's ten layers) | F4: Source
B5: HubSpot (Marketing/Sales Hub + Breeze / Agent Hub) | C5: Per-seat tiers x hubs + HubSpot Credits ($10/1,000) + outcome agents | D5: Pro seat ~$90-100/mo; agents $0.50/resolved convo, $1/recommended lead; Year-1 ~$31,800 for a 50-person team; onboarding $1,500-7,000 | E5: CRM, content, some prospecting and service. Not the full autonomous motion. | F5: getmacha, martechspace, usagepricing, vantagepoint (2026)
B6: Salesforce Agentforce | C6: Flex Credits ($0.005/credit; $0.10/action, $0.15/voice), or $2/conversation, or $125/user digital labor | D6: Mid-market ~$1,250-4,200/mo licenses, plus Data Cloud $65k-175k/yr; implementation 5-11 months | E6: Agentic actions inside Salesforce. Needs Service Cloud + Data Cloud. Not a GTM engine. | F6: help.salesforce, coworker.ai, getclientell, concret.io (2026)
B7: Clari (+ Salesloft) | C7: Per-seat, per module, annual, quote-only | D7: $100-310/user/mo full stack; SMB avg ~$72k/yr, enterprise avg ~$362k/yr; implementation $15k-75k | E7: Forecasting, pipeline inspection, engagement. Visibility, not execution. | F7: docket.io, marketbetter, spendhound, hackingdemand (2026)
B8: 11x (Alice / Julian) | C8: AI-SDR digital worker, annual, quote-only, on leads contacted | D8: From $36k/yr; typically ~$5k/mo, Year-1 $50-60k; ~$1.67/contact; Julian Voice $5,333/mo | E8: Outbound only (one of ten layers). | F8: 11x.ai, altitudebiz, formanorden, breakout (2026)
B9: Artisan (Ava) / AiSDR | C9: AI-BDR subscription + credits | D9: Artisan $600-5,000/mo (30k credits); AiSDR $250-2,500/mo (transparent) | E9: Outbound only. | F9: 11x.ai/guides, cleanlist, miniloop (2026)
B10: Apollo.io | C10: Per-seat + credits (email 1 cr, phone 8 cr) | D10: $49-149/user/mo; overage $25/1,000 credits; active teams $150-400/user | E10: Lead data + sequencing. A rail RAI orchestrates, not the brain. | F10: apollo.io, docket.io, hackingdemand, puzzleinbox (2026)
B11: Clay | C11: Pure usage credits, unlimited seats (Data Credits + Actions) | D11: Launch $185/mo, Growth $495/mo; Enterprise from $30k/yr | E11: Enrichment / waterfall. A rail, not the motion. | F11: clay.com, landbase, cleanlist, salesmotion (2026)
B12: The stack RAI replaces (representative mid-market, ~5 seats) | C12: Sum of point tools + headcount | D12: ~$4,000-8,000/mo in tools (Apollo + Clay + Outreach/Salesloft + HubSpot + AI SDR + content + BI) plus SDR headcount and a RevOps orchestrator | E12: Ten layers, spread across 20+ tools, glued by a human | F12: Composed from the rows above (2026)
B13: RAI (Adya) | C13: Subscription + usage credits + integrations | D13: Free / Startup $99 / Growth $499 / Scale $1,999/mo / Enterprise from $102k/yr | E13: All ten layers. One brain, one memory, one loop. | F13: This model
B15: Reading | C15: The single-function tools (11x, Apollo, Clay) reveal how much a slice costs on its own; the suites (HubSpot, Agentforce, Clari) reveal how the incumbents package seats plus credits. RAI is priced to sit under the replaced stack at every size while doing the whole job.

Sheet Credits
A1: RAI Credits | the meter on the work RAI actually does
A2: One credit is about one email reach-out, roughly one cent. Every action RAI takes draws credits by weight, so a light email and a costly voice minute are priced fairly against each other. Tiers include a monthly pool; beyond it, credits come from packs.
B4: Credit price | C4: $/credit | D4: $/1,000 | E4: When
B5: Retail (overage) | C5: =Accelerators!C7 -> 0.01 | D5: =Accelerators!C7*1000 -> 10 | E5: Pay-as-you-go beyond the included pool. Matches HubSpot credit pricing.
B6: Committed pack | C6: =Accelerators!C8 -> 0.007 | D6: =Accelerators!C8*1000 -> 7 | E6: Pre-committed for the term.
B7: Enterprise pool | C7: =Accelerators!C9 -> 0.005 | D7: =Accelerators!C9*1000 -> 5 | E7: Large pre-committed pools. Matches Agentforce Flex Credits.
B9: Action | C9: Credits | D9: ~ $ each | E9: Notes
B10: Email reach-out (sent) | C10: 1 | D10: =C10*Accelerators!C7 -> 0.01 | E10: The anchor. One credit, ~one cent, one send.
B11: Inbound reply drafted | C11: 2 | D11: =C11*Accelerators!C7 -> 0.02 | E11: RAI drafts; a human approves before it goes.
B12: LinkedIn connect request | C12: 3 | D12: =C12*Accelerators!C7 -> 0.03 | E12: Via Unipile. Respects the weekly send governors.
B13: LinkedIn message / InMail | C13: 4 | D13: =C13*Accelerators!C7 -> 0.04 | E13: Personalised by variable substitution from templates.
B14: WhatsApp / SMS message | C14: 3 | D14: =C14*Accelerators!C7 -> 0.03 | E14: Plus WABA/MSG91 conversation fees passed through.
B15: Voice AI call | C15: 25 | D15: =C15*Accelerators!C7 -> 0.25 | E15: Per minute. Plus telephony minutes passed through.
B16: Lead sourced + verified | C16: 3 | D16: =C16*Accelerators!C7 -> 0.03 | E16: Multi-source (Prospeo primary + agreement). Bundles the data cost at SMB tiers.
B17: Contact / company enrichment | C17: 2 | D17: =C17*Accelerators!C7 -> 0.02 | E17: Firmographic and persona fill.
B18: Signal check (per account, per category) | C18: 1 | D18: =C18*Accelerators!C7 -> 0.01 | E18: Hiring, ads, intent, posts, financial, and so on.
B19: Social post / caption | C19: 5 | D19: =C19*Accelerators!C7 -> 0.05 | E19: For inbound and community.
B20: Image | C20: 20 | D20: =C20*Accelerators!C7 -> 0.2 | E20: On-brand image asset.
B21: Infographic | C21: 40 | D21: =C21*Accelerators!C7 -> 0.4 | E21: Multi-element designed asset.
B22: Newsletter issue | C22: 60 | D22: =C22*Accelerators!C7 -> 0.6 | E22: Written and formatted, hosted natively.
B23: Short video | C23: 250 | D23: =C23*Accelerators!C7 -> 2.5 | E23: Generated short-form video.
B24: Deep research run | C24: 200 | D24: =C24*Accelerators!C7 -> 2 | E24: Full research pass on a market, account or competitor.
B25: Strategy synthesis / plan | C25: 300 | D25: =C25*Accelerators!C7 -> 3 | E25: A planned motion or campaign strategy.
B26: BI report / dashboard on demand | C26: 30 | D26: =C26*Accelerators!C7 -> 0.3 | E26: Generated by the data-analyst agent.
B27: Ad creative + campaign setup | C27: 15 | D27: =C27*Accelerators!C7 -> 0.15 | E27: Ad spend itself is pass-through, not credits.
B28: Meeting booked (outcome) | C28: 50 | D28: =C28*Accelerators!C7 -> 0.5 | E28: Optional outcome credit, for outcome-based deals.
B30: What a pool buys | C30: Example: Growth's 15,000 credits/mo is about 15,000 emails, or 3,750 LinkedIn messages, or 5,000 verified leads, or 750 images, or a blend across all of them. Scale's 60,000 and Enterprise's 400,000 scale the same way. Weights are inputs; tune them against real cost once pilots run.

Sheet Integrations
A1: RAI Integrations | the thirty-plus tools RAI drives, and the channels it runs on
A2: RAI is the brain; these are the plumbing. Each tier includes a number of integration slots; beyond that each active integration is a small monthly fee. Channel infrastructure (mailboxes, LinkedIn accounts, WhatsApp and voice numbers) is priced per unit. Heavy third-party usage is passed through at cost plus handling.
B4: Class | C4: Integrations (shown as logos in the deck) | D4: Count | E4: How it is billed
B5: CRM | C5: HubSpot, Salesforce, Zoho, Pipedrive | D5: 4 | E5: Integration slot fee. RAI can also run its own built-in CRM.
B6: Mail | C6: Gmail, Outlook / M365, Zoho Mail | D6: 3 | E6: Slot fee; mailboxes are the metered unit (below).
B7: Data / enrichment | C7: Prospeo, Apollo, Lusha, Icypeas, FullEnrich | D7: 5 | E7: Slot fee + data passed through at cost + handling, or bundled in credits at SMB tiers.
B8: Scraping | C8: Apify, Serper / Tavily | D8: 2 | E8: Slot fee + volume passed through (Apify ~$4/1,000).
B9: LinkedIn | C9: Unipile | D9: 1 | E9: Slot fee; LinkedIn accounts are the metered unit (below).
B10: Messaging | C10: WhatsApp / WABA, MSG91, Kalyera | D10: 3 | E10: Slot fee + per-conversation fees passed through.
B11: Mailbox infra | C11: InboxKit | D11: 1 | E11: Slot fee; mailboxes metered per unit.
B12: Voice / telephony | C12: Voice agent, telephony provider | D12: 2 | E12: Slot fee + per-minute passed through.
B13: Ad channels | C13: Google Ads, Meta Ads, LinkedIn Ads, Reddit Ads | D13: 4 | E13: Slot fee; ad spend is the customer's own, passed through.
B14: Social | C14: X / Twitter, Reddit, LinkedIn Pages | D14: 3 | E14: Slot fee.
B15: Calendar | C15: Google Calendar, Calendly | D15: 2 | E15: Slot fee.
B16: BI / analytics | C16: Segment / analytics, dashboards | D16: 2 | E16: Slot fee; RAI also has a built-in BI agent.
B17: Total standard integrations | D17: 32 | E17: Custom integrations beyond these are built as a service (see Services).
B19: Metered unit | C19: Rate | D19: Unit | E19: Notes
B20: Integration slot (beyond included) | C20: =Accelerators!C33 -> 25 | D20: per integration / mo | E20: Each active integration past the tier's included slots.
B21: Mailbox (all-in) | C21: =Accelerators!C34 -> 5 | D21: per mailbox / mo | E21: Host + warm-up + infra. From the Affinity model.
B22: Domain | C22: =Accelerators!C35 -> 12 | D22: per domain / yr | E22: One-time annual.
B23: LinkedIn account (Scale rate) | C23: =Accelerators!C36 -> 199 | D23: per account / mo | E23: Rented, Sales Navigator bundled. Growth/Starter/BYO rates on Accelerators.
B24: WhatsApp number (WABA) | C24: =Accelerators!C41 -> 40 | D24: per number / mo | E24: Plus per-conversation fees passed through.
B25: Voice number + telephony base | C25: =Accelerators!C42 -> 30 | D25: per number / mo | E25: Plus per-minute passed through.
B26: Brand workspace | C26: =Accelerators!C32 -> 250 | D26: per workspace / mo | E26: Extra brand/tenant. The scaling lever for agencies and VC portfolios.
B28: Pass-through policy | C28: Third-party data (Prospeo ~$0.01/lead, Apify ~$4/1,000), WhatsApp conversations, telephony minutes, LLM tokens and ad spend are billed at cost plus a 10% handling fee at Scale and Enterprise (transparent), or bundled into credits at the self-serve tiers (simple). The lead-gen waterfall runs Serper/Tavily then Apify then Prospeo, with Icypeas/FullEnrich as fallback: about $0.013-0.024 per verified lead all in.

Sheet Accelerators
A1: RAI Accelerators | the engine that grows an account
A2: Every rate QuoteBuilder uses lives here, so there is one source of truth. Price rises as the account adds seats, credits, channels, integrations and brands. Blue cells are inputs you can edit.
B4: GLOBAL ASSUMPTIONS | C4: Value | E4: Notes
B5: FX rate (INR per USD) | C5: 96 | E5: Used to convert self-serve list prices to India rupees.
B6: India self-serve factor | C6: 0.45 | E6: India self-serve tiers = global USD x FX x this factor. Enterprise is quoted in USD.
B7: RAI Credit price, retail ($/credit) | C7: 0.01 | E7: One credit ~ one email reach-out. Matches the $0.01-per-reach-out economics. HubSpot credits are ~$0.01 too.
B8: RAI Credit price, committed ($/credit) | C8: 0.007 | E8: Price when credits are pre-committed for the term.
B9: RAI Credit price, enterprise ($/credit) | C9: 0.005 | E9: Large pre-committed pools. Matches Agentforce Flex Credits ($0.005).
B10: Pass-through handling markup | C10: 0.1 | E10: Third-party data, WhatsApp, telephony and ad spend billed at cost plus this handling.
B12: DEPLOYMENT MULTIPLIER | C12: Multiple | D12: One-time impl ($) | E12: When it applies
B13: SaaS (default) | C13: 1 | D13: 0 | E13: Multi-tenant cloud. Almost every RAI deal. RAI touches live external channels, so on-prem is rare.
B14: Private / BYOC | C14: 1.3 | D14: 12000 | E14: Customer's own cloud for data-residency or security review. Enterprise / regulated.
B15: On-prem / self-hosted | C15: 1.65 | D15: 35000 | E15: Full self-host. Uncommon for a GTM engine; partner-led only.
B17: SERVICE LEVEL MULTIPLIER | C17: Multiple | E17: What Adya does
B18: Self-serve | C18: 1 | E18: Customer runs RAI themselves. Software only.
B19: Assisted (co-pilot) | C19: 1.25 | E19: Adya helps configure, launch and optimise the motion.
B20: Fully-managed (done-for-you) | C20: 1.6 | E20: Adya runs the whole motion for a team that cannot hire sales. Core RAI wedge for SMBs.
B22: COMMITMENT DISCOUNT | C22: Discount | E22: Applies to recurring RAI fees, not to pass-through
B23: Monthly | C23: 0 | E23: No commitment, list price.
B24: Annual | C24: 0.15 | E24: 12-month term paid annually.
B25: 2-year | C25: 0.22 | E25: Two-year term.
B26: 3-year | C26: 0.28 | E26: Three-year term, best rate.
B29: PER-UNIT RATE CARD (beyond what a tier includes) | C29: Rate | D29: Unit | E29: Notes
B30: Operator seat | C30: 99 | D30: per seat / mo | E30: Full user: configures campaigns, approves replies, reads analytics. Deliberately cheap vs Clari ($200-310/seat) because RAI is not priced per human.
B31: Rep-visibility seat | C31: 15 | D31: per seat / mo | E31: Read-only performance visibility for a sales team (the 200-rep visibility case). Very cheap.
B32: Brand workspace | C32: 250 | D32: per workspace / mo | E32: An extra brand/tenant beyond the tier's included workspaces. The scaling lever for agencies and VC portfolios.
B33: Integration slot | C33: 25 | D33: per integration / mo | E33: Each active integration beyond the tier's included slots.
B34: Mailbox (all-in) | C34: 5 | D34: per mailbox / mo | E34: Host + warm-up + infra. From the Affinity model ($3 + $1 + $1). No separate creation fee.
B35: Domain | C35: 12 | D35: per domain / yr (one-time annual) | E35: Sending domain. Treated as a one-time annual cost (~$11-12), not monthly.
B36: LinkedIn account, Scale (21+) | C36: 199 | D36: per account / mo | E36: Rented account with Sales Navigator bundled. Packaged all-in per the LinkedIn BRD (Model B).
B37: LinkedIn account, Growth (6-20) | C37: 219 | D37: per account / mo | E37: Packaged all-in, 6-20 accounts.
B38: LinkedIn account, Starter (1-5) | C38: 239 | D38: per account / mo | E38: Packaged all-in, 1-5 accounts.
B39: LinkedIn account, BYO | C39: 79 | D39: per account / mo | E39: Customer brings their own LinkedIn; Adya platform + automation fee only.
B40: Sales Navigator add-on | C40: 149 | D40: per account / mo | E40: Only if not already bundled ($139 at Scale).
B41: WhatsApp number (WABA) | C41: 40 | D41: per number / mo | E41: Plus per-conversation WABA fees passed through at cost + handling.
B42: Voice number + telephony base | C42: 30 | D42: per number / mo | E42: Plus per-minute telephony passed through at cost + handling.
B44: Note | E44: LinkedIn bulk tiers mirror LinkedRent: 1-4 accounts 0%, 5-9 5%, 10-19 10%, 20+ 15%. QuoteBuilder uses the Scale rate by default; pick the row that matches the account count for a precise quote.

Sheet Services
A1: RAI Services | onboarding and customization, one-time plus recurring
A2: The done-for-you work that gets a customer live and keeps them ahead. One-time fees scale small / medium / large by scope. Some carry a recurring add-on. Assisted and fully-managed service levels (see Accelerators) sit on top of these.
B4: Service | C4: Small $ | D4: Medium $ | E4: Large $ | F4: Recurring | G4: What it covers
B5: Onboarding & GTM strategy build | C5: 2000 | D5: 6000 | E5: 12000 | F5: included in tier | G5: Company, products, ICP, personas, geo, brand voice, positioning, plus the same profile per competitor and the channel plan. Included assisted at Growth+.
B6: Brand-voice + template library training | C6: 1500 | D6: 4000 | E6: 10000 | F6: - | G6: Learns the voice from past content across hundreds of parameters and builds the personalised template library.
B7: Domain + mailbox infrastructure setup | C7: 500 | D7: 1500 | E7: 4000 | F7: - | G7: Domains, mailboxes, warm-up and deliverability infra. Scales with the number of mailboxes and domains.
B8: Custom integration build (beyond the 30) | C8: 3000 | D8: 8000 | E8: 20000 | F8: +$75/mo | G8: A connector RAI does not ship out of the box.
B9: Custom workflow / play | C9: 2500 | D9: 7500 | E9: 20000 | F9: - | G9: A bespoke ABM, drip or signal play wired into RAI.
B10: CRM / BI migration & sync | C10: 2000 | D10: 6000 | E10: 15000 | F10: - | G10: Move and sync an existing CRM or BI tool so RAI runs against it.
B11: Custom voice-agent build | C11: 3000 | D11: 8000 | E11: 18000 | F11: +$150/mo | G11: Persona, scripts and telephony for the voice AI agent.
B12: Dedicated deliverability management | C12: - | D12: - | E12: - | F12: +$500/mo | G12: Ongoing warm-up, throttles, invite aging and suppression tuning to guard the domain and LinkedIn accounts.
B13: Multi-tenant / white-label setup | C13: 5000 | D13: 15000 | E13: 40000 | F13: per workspace | G13: For agencies and VC firms running many brands under one roof.
B14: Self-improving copy model (fine-tuned SLM) | C14: 25000 | D14: 60000 | E14: 150000 | F14: + hosting | G14: Graduates outbound from template selection to generated copy that learns from RAI's own send-and-track loop. Enterprise only.
B16: Note | C16: Small / medium / large is set by scope: number of sources, locales, mailboxes, brands or workflow complexity. Pick the column that fits the deal in QuoteBuilder.

Sheet QuoteBuilder
A1: RAI QuoteBuilder | live deal calculator
A2: Set the blue cells. Green cells pull rates from the other tabs; black cells are formulas. Prefilled with a worked agency example: a growth-stage agency running GTM for its own brand plus five client brands.
B4: 1) DEAL SHAPE | C4: Choice | E4: Pick from the dropdown
B5: Tier | C5: Scale | E5: Free / Startup / Growth / Scale / Enterprise
B6: Service level | C6: Assisted (co-pilot) | E6: Self-serve / Assisted / Fully-managed
B7: Deployment | C7: SaaS (default) | E7: SaaS / Private / On-prem
B8: Commitment | C8: Annual | E8: Monthly / Annual / 2-year / 3-year
B9: Base fee (from tier) | C9: {=IFERROR(INDEX(Pricing!$C$15:$C$19,MATCH(C5,Pricing!$B$15:$B$19,0)),0)} -> 1999 | E9: Monthly platform fee for the chosen tier. Enterprise base is a floor; edit for the quoted deal.
B10: Service-level multiplier | C10: {=IFERROR(INDEX(Accelerators!C18:C20,MATCH(C6,Accelerators!B18:B20,0)),1)} -> 1.25
B11: Deployment multiplier | C11: {=IFERROR(INDEX(Accelerators!C13:C15,MATCH(C7,Accelerators!B13:B15,0)),1)} -> 1
B12: Deployment one-time impl | C12: {=IFERROR(INDEX(Accelerators!D13:D15,MATCH(C7,Accelerators!B13:B15,0)),0)} -> 0
B13: Commitment discount | C13: {=IFERROR(INDEX(Accelerators!C23:C26,MATCH(C8,Accelerators!B23:B26,0)),0)} -> 0.15
B15: 2) RAI RECURRING (per month) | C15: Qty | D15: $ / mo | E15: These are marked up by service level, deployment and commitment
B16: Platform base fee | C16: 1 | D16: =C9 -> 1999 | E16: One base fee for the tier.
B17: Operator seats (total) | C17: 8 | D17: {=MAX(0,C17-IFERROR(INDEX(Pricing!$D$15:$D$19,MATCH(C5,Pricing!$B$15:$B$19,0)),0))*Accelerators!C30} -> 297 | E17: Included in tier is pulled automatically; you pay only for the excess. Rate $99/seat.
B18: Rep-visibility seats (total) | C18: 0 | D18: {=MAX(0,C18-IFERROR(INDEX(Pricing!$E$15:$E$19,MATCH(C5,Pricing!$B$15:$B$19,0)),0))*Accelerators!C31} -> 0 | E18: For sales-team performance visibility. Cheap.
B19: Brand workspaces (total) | C19: 6 | D19: {=MAX(0,C19-IFERROR(INDEX(Pricing!$J$15:$J$19,MATCH(C5,Pricing!$B$15:$B$19,0)),0))*Accelerators!C32} -> 750 | E19: Own brand + five client brands = 6. Three included at Scale, three billed.
B20: Active integrations (total) | C20: 24 | D20: {=MAX(0,C20-IFERROR(INDEX(Pricing!$G$15:$G$19,MATCH(C5,Pricing!$B$15:$B$19,0)),0))*Accelerators!C33} -> 100 | E20: Twenty included at Scale; four billed.
B21: Mailboxes (total) | C21: 60 | D21: {=MAX(0,C21-IFERROR(INDEX(Pricing!$H$15:$H$19,MATCH(C5,Pricing!$B$15:$B$19,0)),0))*Accelerators!C34} -> 175 | E21: Twenty-five included at Scale; thirty-five billed at $5.
B22: LinkedIn accounts (total) | C22: 14 | D22: {=MAX(0,C22-IFERROR(INDEX(Pricing!$I$15:$I$19,MATCH(C5,Pricing!$B$15:$B$19,0)),0))*Accelerators!C36} -> 1592 | E22: Six included at Scale; six billed at the Scale rate (Sales Navigator bundled).
B23: WhatsApp numbers | C23: 1 | D23: =C23*Accelerators!C41 -> 40 | E23: Number fee only; conversations are pass-through below.
B24: Voice numbers | C24: 1 | D24: =C24*Accelerators!C42 -> 30 | E24: Number fee only; minutes are pass-through below.
B25: Credits used / mo (total) | C25: 200000 | D25: {=MAX(0,C25-IFERROR(INDEX(Pricing!$F$15:$F$19,MATCH(C5,Pricing!$B$15:$B$19,0)),0))*Accelerators!C7} -> 1400 | E25: Sixty thousand included at Scale; the rest at retail. Buy a committed pack to lower the rate.
B26: RAI recurring subtotal (pre-multiplier) | D26: =SUM(D16:D25) -> 6383 | E26: Sum of the lines above.
B27: Adjusted recurring / mo | D27: =D26*C10*C11*(1-C13) -> 6781.9375 | E27: Subtotal x service level x deployment x (1 - commitment discount).
B29: 3) PASS-THROUGH (per month, at cost + handling) | C29: Cost $ | D29: $ / mo | E29: Not marked up by service level or commitment
B30: WhatsApp / SMS conversations | C30: 150 | D30: =C30*(1+Accelerators!C10) -> 165 | E30: WABA / MSG91 conversation fees.
B31: Voice telephony minutes | C31: 200 | D31: =C31*(1+Accelerators!C10) -> 220 | E31: Per-minute telephony.
B32: Third-party data / enrichment | C32: 400 | D32: =C32*(1+Accelerators!C10) -> 440 | E32: Prospeo, Apify and fallbacks, at cost.
B33: Ad spend | C33: 0 | D33: =C33*(1+Accelerators!C10) -> 0 | E33: The customer's own ad budget, passed straight through (0 here).
B34: Pass-through subtotal / mo | D34: =SUM(D30:D33) -> 825 | E34: At cost plus handling.
B36: 4) ONE-TIME (setup & services) | D36: $ | E36: From Services + deployment impl
B37: Multi-brand onboarding & strategy (M) | D37: 6000 | E37: Six brands.
B38: Brand-voice + template training (M) | D38: 4000 | E38: Shared across brands.
B39: Domain + mailbox infrastructure (L) | D39: 4000 | E39: Sixty mailboxes.
B40: Custom integration (M) | D40: 8000 | E40: One bespoke connector.
B41: CRM / BI migration (M) | D41: 6000 | E41: Sync the agency's stack.
B42: Custom voice-agent build (S) | D42: 3000 | E42: One voice persona.
B43: Multi-tenant / white-label setup (M) | D43: 15000 | E43: Agency running many brands.
B44: Deployment implementation | D44: =C12 -> 0 | E44: Pulled from the deployment choice (SaaS = 0).
...
