Workbook

Sheet README
A1: Adya RAS | Pricing Model 2.0
A2: How to read and use this workbook. Every blue number is an input you can edit. Black numbers are formulas that recalculate off the inputs.
B4: What this replaces | C4: The old file priced every tier as one flat seat price (roughly $149 per seat) multiplied by headcount, with a small volume discount. That leaves enterprise money on the table, overcharges small teams, and has no way to price customization or to grow an account. This model fixes all of that.
B5: The five-layer stack | C5: Every RAS deal is built from five layers: (1) a Platform base fee by tier, (2) Seats split into Builder and Viewer, (3) RAS Credits for usage, (4) a Governance and Deployment premium, and (5) Customization and Services delivered through the AI ELT. The tabs below hold each layer.
B7: Tab | C7: What it holds
B8: Pricing | C8: List pricing for all four tiers: Individual, Team, Business, Enterprise. Global ($) and India (₹) columns.
B9: Segments | C9: Who each tier is for (ICP and buyer personas), what they pay today, and willingness to pay. This justifies the numbers.
B10: Benchmark | C10: How RAS pricing compares to Claude Science, Glean, Snowflake, Databricks, AlphaSense and Hebbia. Sourced, dated.
B11: Credits | C11: What one RAS Credit is and how each action draws it down. This is the elastic usage meter.
B12: Accelerators | C12: The rate card that makes price grow with the account: seats, workspaces, variables, integrations, documents, ontologies, models, credit packs.
B13: Customization | C13: The services rate card for the AI ELT work: integrations, localizations, deployment, LLM change and fine-tune, workflows, ontologies, data onboarding. One-time plus recurring.
B14: QuoteBuilder | C14: A live calculator. Pick a tier, a deployment, seats, credits and any customization, and it returns one-time cost, annual recurring, and Year-1 ACV. Prefilled with a worked mid-market example.
B16: Colour legend
B17: Blue text | C17: An input. Change it and the model updates.
B18: Black text | C18: A formula. Do not overwrite; it derives from inputs.
B19: Green text | C19: A link that pulls a number from another tab.
B20: Yellow fill | C20: A key assumption or a cell you should set for your deal.
B22: Note | C22: All numbers are starting hypotheses anchored to competitor pricing and to RAS willingness-to-pay. Calibrate against pilot data before quoting. Enterprise is partner-led per the locked ICP.

Sheet Pricing
A1: RAS List Pricing | four tiers
A2: The published shape of each tier. Business and Enterprise then grow through Accelerators and Customization. Enterprise is a floor, not a ceiling.
B4: Line | C4: Individual | D4: Team | E4: Business | F4: Enterprise
B5: Platform base ($/mo) | C5: 49 | D5: 499 | E5: 1999 | F5: 8500
B6: Platform base (₹/mo) | C6: =Pricing!C5*Accelerators!$C$5*Accelerators!$C$6 -> 1940.4 | D6: =Pricing!D5*Accelerators!$C$5*Accelerators!$C$6 -> 19760.4 | E6: =Pricing!E5*Accelerators!$C$5*Accelerators!$C$6 -> 79160.4 | F6: =Pricing!F5*Accelerators!$C$5*Accelerators!$C$6 -> 336600
B7: Platform base ($/yr) | C7: =Pricing!C5*12 -> 588 | D7: =Pricing!D5*12 -> 5988 | E7: =Pricing!E5*12 -> 23988 | F7: =Pricing!F5*12 -> 102000
B9: What the base includes
B10: Builder seats included | C10: 1 | D10: 3 | E10: 5 | F10: 10
B11: Viewer seats included | C11: 0 | D11: 5 | E11: 20 | F11: 50
B12: Active workspaces | C12: 1 | D12: 5 | E12: 20 | F12: Unlimited*
B13: Documents in index | C13: 100 | D13: 1000 | E13: 10000 | F13: 100000
B14: RAS Credits / mo | C14: 200 | D14: 2000 | E14: 8000 | F14: 40000
B15: Max pages / document | C15: 50 | D15: 300 | E15: 500 | F15: Custom
B17: Platform and governance
B18: SSO / SAML | C18: — | D18: — | E18: Yes | F18: Yes
B19: Audit logs / data residency | C19: — | D19: — | E19: Standard | F19: Full AGP
B20: MCP / SDK / PaaS | C20: — | D20: — | E20: Yes | F20: Yes
B21: Deployment options | C21: SaaS | D21: SaaS | E21: SaaS / BYOC | F21: Any (see multiplier)
B22: SLA | C22: — | D22: — | E22: Business | F22: Custom
B23: Overage | C23: Upgrade | D23: Credit packs | E23: Credit packs | F23: Committed pool
B24: Motion | C24: Self-serve | D24: Self-serve | E24: Direct / light-touch | F24: Partner-led
B26: * Enterprise workspaces unlimited under fair use. Everything beyond the included amounts is priced on the Accelerators tab. Enterprise base is a platform floor; typical Year-1 ACV builds well past it once seats, credits, deployment and customization are added (see QuoteBuilder).

Sheet Segments
A1: Segments | who buys RAS and what they will pay
A2: Pulled from the locked RAS ICP and the ABM persona ladder, matched to the competitor anchors on the Benchmark tab. This is the justification layer for the numbers.
B4: Segment | C4: ICP and who benefits | D4: Buyer personas | E4: What they pay today | F4: RAS target
B5: Individual | C5: Individual researchers and academics; college programmes (RAS is taught at ~20 universities); solo analysts; very early life-sciences and fintech founders. | D5: User = the researcher or analyst. Buys their own seat. No procurement. | E5: A prosumer AI subscription ($20-200/mo) plus DIY search. A single AlphaSense or Hebbia seat ($10-20k/yr) is out of reach. | F5: $49/mo (academic $19/mo or free via programme). A wedge, not a profit centre. Feeds bottoms-up into teams.
B6: Mid-sized company | C6: Life-sciences startups, boutique investment banks, VC and PE funds, fintechs, CDMOs, mutual-fund companies. The direct-GTM sweet spot. India first, US second. | D6: User = analysts and scientists (build workspaces). Influencer = CIO or COO type. Decision maker = CEO or CTO depending on size. | E6: A boutique fund pays ~$45-60k for 3 AlphaSense seats, or runs 3-10 analysts (India ~₹8-25L each). Plus PitchBook, Bloomberg, consultants. | F6: Business tier landing ~$30-80k/yr. Undercuts the AlphaSense stack while delivering the whole evidence-to-decision loop.
B7: Enterprise | C7: BFSI, pharma and pharma-allied, large IBs, government. Partner-led only (Adya has no direct enterprise sales muscle yet). Named accounts stay credibility proof points. | D7: User = researchers and scientists. Influencer = CIO or COO. Decision maker = CEO, CTO or the board. Champion or blocker = head of tech or GTM. | E7: AlphaSense large customers $1M+; Glean mid-large TCO $350-480k; Databricks median ~$250k/yr. Plus a research team and consultants. | F7: From $102k/yr platform floor, building to $250k-$1M+ once deployment, credits, seats and AI ELT customization are added.
B9: Willingness-to-pay logic
B10: The value RAS displaces per seat is large: it replaces a ten-subscription stack (AlphaSense, Hebbia, Bloomberg, PitchBook, CB Insights, Gartner, Forrester, plus DIY AI and BI tools) and a slice of a research team. That is the WTP ceiling.
B11: Individual is priced at the prosumer floor because that buyer compares RAS to a $20-200/mo subscription, not to an enterprise seat. The goal is adoption and academic reach, not margin.
B12: Mid-market has the strongest margin case: the buyer already pays five figures for AlphaSense or carries analyst salaries, so a $30-80k RAS deal reads as a saving while being real revenue for Adya.
B13: Enterprise WTP is set by governance and sovereignty, not seat count. AGP plus on-prem or air-gapped deployment is what a bank or pharma pays a premium for, which is why deployment is a multiplier here.

Sheet Benchmark
A1: Competitive Benchmark | how RAS should be priced against the field
A2: Current, dated figures for the tools you named plus your two closest direct competitors. Note the pattern: the market is converging on base + seats + usage credits + a governance premium + services.
B4: Vendor | C4: Pricing model | D4: Headline numbers | E4: What the higher tier gates | F4: Read-across for RAS
B5: Claude Science | C5: Bundled into the Claude subscription | D5: Pro $20/mo; Max $100-200/mo; Team and Enterprise custom | E5: More usage and admin, not a separate science price | F5: Sets the ceiling for an Individual plan. RAS individual must live near a prosumer subscription, not an enterprise seat.
B6: Glean | C6: Per seat + usage credits + platform + support % | D6: ~$50/user/mo base, +$15 for Work AI; ~100-seat / ~$60k floor; mid-large TCO $350-480k | E6: AI agents, BYOC, deeper indexing | F6: The closest structural template: seats plus metered credits plus implementation. RAS should mirror this shape.
B7: Snowflake | C7: Pure consumption (credits) + storage | D7: Std $2 / Ent $3 / Biz-Critical $4 / VPS $6 per credit; storage ~$23/TB; commit 25-45% off | E7: Governance and isolation cost a higher per-credit rate | F7: Governance is a price lever, not a feature checkbox. Editions that add governance charge 1.5-3x per unit.
B8: Databricks | C8: Pure consumption (DBU) + cloud infra | D8: $0.07 to $1.00+/DBU; Premium ~+37% vs Std; commit 20-40% off; median customer ~$250k/yr | E8: Unity Catalog, audit, HIPAA, private link | F8: Same lesson: higher governance tier raises the unit rate. Committed use earns a discount. Abstract the meter (DBU) so price is not raw seats.
B9: AlphaSense | C9: Per seat + content + expert-call credits; now adding consumption | D9: $10-20k/seat; $40k+ with expert calls; avg deal $50-100k; large $1M+ | E9: Expert calls, internal-data integration, hosting | F9: Direct competitor and a WTP ceiling. Notably it is shifting off flat seats toward consumption, which validates the hybrid model.
B10: Hebbia | C10: Two-tier flat seat, unlimited under fair use | D10: Professional ~$10k/seat/yr (builders); Lite $3-3.5k/seat/yr (consumers) | E10: Agent building, advanced integrations | F10: Direct competitor. The Builder vs Viewer split maps exactly onto the RAS persona ladder and is a proven land-and-expand engine.
B11: Bloomberg Terminal | C11: Flat per seat (the before-stack anchor) | D11: ~$30k/seat/yr | E11: n/a | F11: Part of the ten-subscription stack RAS replaces. Frames the 'research team in one product' value.
B12: Adya RAS 2.0 | C12: Base + Builder/Viewer seats + Credits + Governance/Deployment premium + AI ELT services | D12: Individual $49/mo; Team $499/mo; Business from $1,999/mo; Enterprise from $102k/yr | E12: Deployment multiplier (SaaS to air-gapped) and full AGP governance | F12: Undercuts AlphaSense and Hebbia per seat while charging for usage, governance and customization the way Snowflake and Databricks do.
B14: Sources (accessed 17 Sep 2026)
B15: Claude subscription tiers and bundled Claude Science: claude.com/pricing; suprmind.ai; cloudzero.com.
B16: Glean: gosearch.ai, workativ.com, checkthat.ai, vendr.com (buyer-reported, Vendr and Forrester data).
B17: Snowflake: Snowflake Service Consumption Table (eff. 1 Sep 2026) via markaicode.com; finout.io; cloudzero.com.
B18: Databricks: flexera.com; cloudzero.com; opslyft.com; costbench.com (Vendr median).
B19: AlphaSense: sacra.com ($700M ARR, seat range), enterprisedna.co (shift to consumption), elevatedsignal.com, vendr.com.
B20: Hebbia: sacra.com and usagepricing.com (Professional/Lite seat tiers), spellbook.com.
B21: Bloomberg Terminal: widely reported ~$30k/seat/yr; used here as a before-stack anchor.

Sheet Credits
A1: RAS Credits | the usage meter
A2: One credit is the base unit of work. Each action draws credits by how much compute it uses. This replaces the old flat query cap with something that scales revenue with heavy use.
B4: Action | C4: Credits drawn | D4: Rationale
B5: Enterprise Search question | C5: 1 | D5: Cheap daily-habit action. Keep it light so search becomes a reflex.
B6: Data Analyst question (text-to-SQL) | C6: 1 | D6: Core proof point (BIRD world #3). Priced to encourage use.
B7: Strategy agent session | C7: 5 | D7: Synthesises across the other agents and firm knowledge.
B8: Deep Research run (standard) | C8: 10 | D8: Multi-source, long running, highest compute.
B9: Deep Research run (deep mode) | C9: 20 | D9: More sources and longer runtime than standard.
B10: Custom workflow run | C10: 8 | D10: A built workflow firing its agent chain. Tune per workflow if needed.
B11: Follow-up in same thread | C11: 1 | D11: Never penalise iterative questioning.
B12: Failed / errored run | C12: 0 | D12: Never charge for a system failure.
B15: Buying more credits
B16: Overage pack (per 1,000) | C16: =Accelerators!$C$9 -> 80 | D16: Mid-term top-up, no commitment.
B17: Committed pool (per 1,000) | C17: =Accelerators!$C$10 -> 50 | D17: Pre-purchased inside an annual or multi-year commit. Cheaper per credit, like Snowflake and Databricks committed use.

Sheet Accelerators
A1: RAS Accelerators | the engine that grows an account
A2: Price rises as the account expands. These per-unit rates apply to anything beyond what a tier includes. QuoteBuilder pulls from here.
B4: Global assumptions | C4: Value | E4: Note
B5: FX rate (₹ per $) | C5: 88 | E5: Edit to today’s rate. Drives the India (₹) columns.
B6: India factor (self-serve tiers) | C6: 0.45 | E6: India list = Global $ x FX x this factor. Reflects lower WTP and PPP for Individual and Team. Enterprise is quoted in USD.
B7: Commit discount: annual | C7: 0.15 | E7: Applied to recurring for a 12-month commitment. Anchored to Snowflake 25-45% and Databricks 20-40% ranges, set conservatively.
B8: Commit discount: 3-year | C8: 0.25 | E8: Applied to recurring for a 36-month commitment.
B9: Credit pack (overage) per 1,000 | C9: 80 | E9: Price of buying more credits mid-term without a commit.
B10: Credit pack (committed) per 1,000 | C10: 50 | E10: Price of credits inside a committed pool.
B12: Scale driver (per unit, per month) | C12: Global ($) | D12: India (₹) | E12: How it works
B13: Extra Builder seat | C13: 150 | D13: =$C$13*Accelerators!$C$5*Accelerators!$C$6 -> 5940 | E13: Analyst, scientist or PM who creates workspaces, workflows and ontologies. Your power user. Anchored below Hebbia Professional ($833/mo).
B14: Extra Viewer seat | C14: 40 | D14: =$C$14*Accelerators!$C$5*Accelerators!$C$6 -> 1584 | E14: Partner, exec or reviewer who reads and asks. Anchored near Hebbia Lite and Glean base logic.
B15: Extra active workspace | C15: 25 | D15: =$C$15*Accelerators!$C$5*Accelerators!$C$6 -> 990 | E15: Each live workspace beyond the tier allowance. Archived workspaces are read-only and free.
B16: Tracked variables (per 100) | C16: 30 | D16: =$C$16*Accelerators!$C$5*Accelerators!$C$6 -> 1188 | E16: Typed nodes in the strategy flow bound to live data. Priced per 100 because heavy models cost more compute.
B17: Active integration (custom / premium) | C17: 75 | D17: =$C$17*Accelerators!$C$5*Accelerators!$C$6 -> 2970 | E17: Each live custom or premium connector. Standard registry connectors are free.
B18: Documents in index (per 10,000) | C18: 60 | D18: =$C$18*Accelerators!$C$5*Accelerators!$C$6 -> 2376 | E18: Active documents or URLs in the index, which also drives storage. Deleting frees capacity.
B19: Active ontology | C19: 250 | D19: =$C$19*Accelerators!$C$5*Accelerators!$C$6 -> 9900 | E19: Each live company or domain ontology in the knowledge graph. Recurring because it is maintained and it compounds.
B20: Active fine-tuned model | C20: 400 | D20: =$C$20*Accelerators!$C$5*Accelerators!$C$6 -> 15840 | E20: Hosting and upkeep of a customer-specific fine-tuned model. The one-time build sits on the Customization tab.
B22: Deployment / governance | C22: Recurring multiplier | D22: One-time implementation | E22: Why the premium
B23: SaaS (Adya cloud) | C23: 1 | D23: 0 | E23: Standard multi-tenant. The baseline.
B24: BYOC (their cloud) | C24: 1.35 | D24: 15000 | E24: Runs in the customer VPC. More ops and support. Anchored to Databricks Premium and Snowflake edition step-ups.
B25: On-prem | C25: 1.75 | D25: 40000 | E25: Customer data centre. Full AGP governance, residency, isolation.
B26: Air-gapped | C26: 2.25 | D26: 90000 | E26: No external network. Highest sovereignty. Anchored above Snowflake VPS ($6 vs $2 per credit).

Sheet Customization
A1: Customization and Services | the AI ELT rate card
A2: Everything a customer can ask for on top of the platform, delivered through the AI ELT. Each item has a one-time build fee by complexity, plus recurring where the work keeps living in the platform.
B4: Service item | C4: S | D4: M | E4: L | F4: Recurring / mo | G4: Method, complexity guide and recurring treatment
B5: Custom integration (connector) | C5: 2000 | D5: 5000 | E5: 12000 | F5: 0 | G5: MCP connector build. S = REST with clean docs. M = auth or pagination quirks. L = legacy or on-prem system. Recurring is the $75/mo per active integration on Accelerators.
B6: Localization pack (language + compliance) | C6: 3000 | D6: 7000 | E6: 18000 | F6: 150 | G6: S = UI and prompts for one language. M = adds regional data formats. L = adds a regulatory framework (for example local data law). Recurring $150/mo per locale kept live.
B7: Deployment implementation | C7: =Accelerators!$D$24 -> 15000 | D7: =Accelerators!$D$25 -> 40000 | E7: =Accelerators!$D$26 -> 90000 | F7: 0 | G7: S = BYOC, M = On-prem, L = Air-gapped. One-time figures link to the deployment table so there is one source. Ongoing cost is the deployment multiplier, not a separate line.
B8: LLM swap / config (their model) | C8: 3000 | D8: 8000 | E8: 20000 | F8: 0 | G8: Point RAS at a customer-preferred or customer-hosted model. S = a supported hosted model. M = a self-hosted endpoint. L = a bespoke gateway with routing rules.
B9: LLM fine-tune (SLM, Model Studio) | C9: 25000 | D9: 60000 | E9: 150000 | F9: 0 | G9: Data prep, training, evals and publishing of a domain small model. S = one narrow lane. M = several lanes. L = a full domain suite. Hosting is $400/mo per model on Accelerators. Sells ~90% inference savings on solved lanes.
B10: Custom workflow build | C10: 5000 | D10: 15000 | E10: 40000 | F10: 0 | G10: A built agent chain for their process. S = up to ~5 steps. M = branching and a few integrations. L = many agents and approvals. Run cost is drawn from credits.
B11: Custom ontology build | C11: 10000 | D11: 30000 | E11: 80000 | F11: 0 | G11: Company or domain knowledge graph and doctrine rules. S = one domain, few entity types. M = multi-domain. L = enterprise-wide. Maintained via the $250/mo per ontology on Accelerators.
B12: AI ELT data onboarding | C12: 8000 | D12: 25000 | E12: 75000 | F12: 0 | G12: Ingest, normalise and structure their data into the fabric. S = a few clean sources. M = several sources with transforms. L = large messy estate, many systems. Ongoing storage and index sits in the documents accelerator.

Sheet QuoteBuilder
A1: Quote Builder | build any deal
A2: Set the yellow and blue cells. The model returns monthly recurring, annual recurring, one-time cost and Year-1 ACV. Prefilled with a mid-market life-sciences / boutique-fund example.
B4: 1. Deal setup
B5: Tier | C5: Business | G5: One of: Individual, Team, Business, Enterprise
B6: Deployment | C6: BYOC (their cloud) | G6: One of: SaaS (Adya cloud), BYOC (their cloud), On-prem, Air-gapped
B7: Commit term | C7: Annual | G7: One of: Monthly, Annual, 3-year
B9: Deployment multiplier | C9: {=INDEX(Accelerators!$C$23:$C$26,MATCH(C6,Accelerators!$B$23:$B$26,0))} -> 1.35
B10: Commit discount | C10: =IF(C7="3-year",Accelerators!$C$8,IF(C7="Annual",Accelerators!$C$7,0)) -> 0.15
B11: Platform base ($/mo) | C11: {=INDEX(Pricing!$C$5:$F$5,MATCH(C5,Pricing!$C$4:$F$4,0))} -> 1999
B13: 2. Seats and usage
B14: Item | C14: You need | D14: Included | E14: Chargeable | F14: $/mo | G14: Unit rate from Accelerators
B15: Builder seats (total) | C15: 8 | D15: {=INDEX(Pricing!$C$10:$F$10,MATCH(C5,Pricing!$C$4:$F$4,0))} -> 5 | E15: =MAX(0,C15-D15) -> 3 | F15: =E15*Accelerators!$C$13 -> 450 | G15: Extra Builder seat
B16: Viewer seats (total) | C16: 25 | D16: {=INDEX(Pricing!$C$11:$F$11,MATCH(C5,Pricing!$C$4:$F$4,0))} -> 20 | E16: =MAX(0,C16-D16) -> 5 | F16: =E16*Accelerators!$C$14 -> 200 | G16: Extra Viewer seat
B17: RAS Credits / mo (total) | C17: 15000 | D17: {=INDEX(Pricing!$C$14:$F$14,MATCH(C5,Pricing!$C$4:$F$4,0))} -> 8000 | E17: =MAX(0,C17-D17) -> 7000 | F17: =E17/1000*(IF(C7="Monthly",Accelerators!$C$9,Accelerators!$C$10)) -> 350 | G17: Committed vs overage per 1,000
B18: Additional active workspaces | C18: 10 | D18: - | E18: =C18 -> 10 | F18: =C18*Accelerators!$C$15 -> 250 | G18: Extra active workspace
B19: Variable blocks (per 100) | C19: 6 | D19: - | E19: =C19 -> 6 | F19: =C19*Accelerators!$C$16 -> 180 | G19: Tracked variables (per 100)
B20: Additional integrations | C20: 4 | D20: - | E20: =C20 -> 4 | F20: =C20*Accelerators!$C$17 -> 300 | G20: Active integration (custom / premium)
B21: Additional document blocks (per 10,000) | C21: 3 | D21: - | E21: =C21 -> 3 | F21: =C21*Accelerators!$C$18 -> 180 | G21: Documents in index (per 10,000)
B22: Additional active ontologies | C22: 1 | D22: - | E22: =C22 -> 1 | F22: =C22*Accelerators!$C$19 -> 250 | G22: Active ontology
B23: Additional fine-tuned models | C23: 0 | D23: - | E23: =C23 -> 0 | F23: =C23*Accelerators!$C$20 -> 0 | G23: Active fine-tuned model
B25: 3. Customization (one-time build via AI ELT)
B26: Service item | C26: Qty | D26: Cmplx | E26: One-time each | F26: One-time total | G26: Recurring/mo total
B27: Custom integration (connector) | C27: 2 | D27: M | E27: {=IFERROR(INDEX(Customization!$C$5:$E$12,MATCH(B27,Customization!$B$5:$B$12,0),MATCH(D27,Customization!$C$4:$E$4,0)),0)} -> 5000 | F27: =C27*E27 -> 10000 | G27: {=C27*IFERROR(INDEX(Customization!$F$5:$F$12,MATCH(B27,Customization!$B$5:$B$12,0)),0)} -> 0
B28: Localization pack (language + compliance) | C28: 0 | E28: {=IFERROR(INDEX(Customization!$C$5:$E$12,MATCH(B28,Customization!$B$5:$B$12,0),MATCH(D28,Customization!$C$4:$E$4,0)),0)} -> 0 | F28: =C28*E28 -> 0 | G28: {=C28*IFERROR(INDEX(Customization!$F$5:$F$12,MATCH(B28,Customization!$B$5:$B$12,0)),0)} -> 0
B29: Deployment implementation | C29: 0 | E29: {=IFERROR(INDEX(Customization!$C$5:$E$12,MATCH(B29,Customization!$B$5:$B$12,0),MATCH(D29,Customization!$C$4:$E$4,0)),0)} -> 0 | F29: =C29*E29 -> 0 | G29: {=C29*IFERROR(INDEX(Customization!$F$5:$F$12,MATCH(B29,Customization!$B$5:$B$12,0)),0)} -> 0
B30: LLM swap / config (their model) | C30: 0 | E30: {=IFERROR(INDEX(Customization!$C$5:$E$12,MATCH(B30,Customization!$B$5:$B$12,0),MATCH(D30,Customization!$C$4:$E$4,0)),0)} -> 0 | F30: =C30*E30 -> 0 | G30: {=C30*IFERROR(INDEX(Customization!$F$5:$F$12,MATCH(B30,Customization!$B$5:$B$12,0)),0)} -> 0
B31: LLM fine-tune (SLM, Model Studio) | C31: 0 | E31: {=IFERROR(INDEX(Customization!$C$5:$E$12,MATCH(B31,Customization!$B$5:$B$12,0),MATCH(D31,Customization!$C$4:$E$4,0)),0)} -> 0 | F31: =C31*E31 -> 0 | G31: {=C31*IFERROR(INDEX(Customization!$F$5:$F$12,MATCH(B31,Customization!$B$5:$B$12,0)),0)} -> 0
B32: Custom workflow build | C32: 2 | D32: S | E32: {=IFERROR(INDEX(Customization!$C$5:$E$12,MATCH(B32,Customization!$B$5:$B$12,0),MATCH(D32,Customization!$C$4:$E$4,0)),0)} -> 5000 | F32: =C32*E32 -> 10000 | G32: {=C32*IFERROR(INDEX(Customization!$F$5:$F$12,MATCH(B32,Customization!$B$5:$B$12,0)),0)} -> 0
B33: Custom ontology build | C33: 1 | D33: M | E33: {=IFERROR(INDEX(Customization!$C$5:$E$12,MATCH(B33,Customization!$B$5:$B$12,0),MATCH(D33,Customization!$C$4:$E$4,0)),0)} -> 30000 | F33: =C33*E33 -> 30000 | G33: {=C33*IFERROR(INDEX(Customization!$F$5:$F$12,MATCH(B33,Customization!$B$5:$B$12,0)),0)} -> 0
B34: AI ELT data onboarding | C34: 1 | D34: M | E34: {=IFERROR(INDEX(Customization!$C$5:$E$12,MATCH(B34,Customization!$B$5:$B$12,0),MATCH(D34,Customization!$C$4:$E$4,0)),0)} -> 25000 | F34: =C34*E34 -> 25000 | G34: {=C34*IFERROR(INDEX(Customization!$F$5:$F$12,MATCH(B34,Customization!$B$5:$B$12,0)),0)} -> 0
B35: Customization subtotal | F35: =SUM(F27:F34) -> 75000 | G35: =SUM(G27:G34) -> 0
B36: Deployment implementation (from deployment choice) | F36: {=INDEX(Accelerators!$D$23:$D$26,MATCH(C6,Accelerators!$B$23:$B$26,0))} -> 15000 | G36: 0 for SaaS; BYOC/On-prem/Air-gapped per table
B38: 4. Deal economics
B39: Recurring subtotal ($/mo, pre-adjust) | C39: =C11+F15+F16+F17+F18+F19+F20+F21+F22+F23+G35 -> 4159
B40: After deployment multiplier | C40: =C39*C9 -> 5614.65
B41: Monthly recurring (after commit discount) | C41: =C40*(1-C10) -> 4772.4525
B42: Annual recurring | C42: =C41*12 -> 57269.43
B43: One-time total (build + deployment impl) | C43: =F35+F36 -> 90000
B44: Year-1 ACV (annual recurring + one-time) | C44: =C42+C43 -> 147269.43
B45: Ongoing ACV (Year 2+) | C45: =C42 -> 57269.43
...
